Workbook

Sheet TestCases
A1: Case ID | B1: Scenario | C1: Actual Label | D1: Expected Attack Type | E1: Source IP | F1: Function Code | G1: Machine Register | H1: Requested Value | I1: Signature Mode | J1: Repeat Count | K1: Seconds Since Last Settle | L1: Current TANK_PRESSURE | M1: Current CONVEYOR_SPEED | N1: Current COOLING_VALVE | O1: Current HEATER_TEMP | P1: Current FEED_PUMP | Q1: Current RELIEF_VALVE | R1: Pending Setpoints (JSON) | S1: Description | T1: Cyber Verdict | U1: Cyber Reason | V1: Physical Verdict | W1: Physical Reason | X1: Final Decision | Y1: Orchestrator Reason | Z1: Detected Attack Type | AA1: Predicted Label | AB1: Outcome
A2: N01 | B2: Operator pressure step | C2: NORMAL | D2: - | E2: 127.0.0.1 | F2: 16 | G2: TANK_PRESSURE | H2: 51 | I2: valid | J2: 1 | K2: 12 | L2: 50 | M2: 0 | N2: 45 | O2: 60 | P2: 40 | Q2: 45 | S2: 50 -> 51 PSI signed operator step | T2: PASS | U2: OK | V2: PASS | W2: OK | X2: PASS | Y2: OK | Z2: - | AA2: NORMAL | AB2: =IF(OR(AA2="",C2=""),"",IF(C2="ATTACK",IF(AA2="ATTACK","TP","FN"),IF(AA2="ATTACK","FP","TN"))) -> TN
A3: N02 | B3: Operator conveyor step | C3: NORMAL | D3: - | E3: 127.0.0.1 | F3: 16 | G3: CONVEYOR_SPEED | H3: 2 | I3: valid | J3: 1 | K3: 12 | L3: 50 | M3: 0 | N3: 45 | O3: 60 | P3: 40 | Q3: 45 | S3: 0 -> 2 RPM | T3: PASS | U3: OK | V3: PASS | W3: OK | X3: PASS | Y3: OK | Z3: - | AA3: NORMAL | AB3: =IF(OR(AA3="",C3=""),"",IF(C3="ATTACK",IF(AA3="ATTACK","TP","FN"),IF(AA3="ATTACK","FP","TN"))) -> TN
A4: N03 | B4: Operator cooling step | C4: NORMAL | D4: - | E4: 127.0.0.1 | F4: 16 | G4: COOLING_VALVE | H4: 46 | I4: valid | J4: 1 | K4: 12 | L4: 50 | M4: 0 | N4: 45 | O4: 60 | P4: 40 | Q4: 45 | S4: 45 -> 46 deg | T4: PASS | U4: OK | V4: PASS | W4: OK | X4: PASS | Y4: OK | Z4: - | AA4: NORMAL | AB4: =IF(OR(AA4="",C4=""),"",IF(C4="ATTACK",IF(AA4="ATTACK","TP","FN"),IF(AA4="ATTACK","FP","TN"))) -> TN
A5: N04 | B5: Operator heater step | C5: NORMAL | D5: - | E5: 127.0.0.1 | F5: 16 | G5: HEATER_TEMP | H5: 61 | I5: valid | J5: 1 | K5: 12 | L5: 50 | M5: 0 | N5: 45 | O5: 60 | P5: 40 | Q5: 45 | S5: 60 -> 61 C | T5: PASS | U5: OK | V5: PASS | W5: OK | X5: PASS | Y5: OK | Z5: - | AA5: NORMAL | AB5: =IF(OR(AA5="",C5=""),"",IF(C5="ATTACK",IF(AA5="ATTACK","TP","FN"),IF(AA5="ATTACK","FP","TN"))) -> TN
A6: N05 | B6: Operator feed pump step | C6: NORMAL | D6: - | E6: 127.0.0.1 | F6: 16 | G6: FEED_PUMP | H6: 41 | I6: valid | J6: 1 | K6: 12 | L6: 50 | M6: 0 | N6: 45 | O6: 60 | P6: 40 | Q6: 45 | S6: 40 -> 41 % | T6: PASS | U6: OK | V6: PASS | W6: OK | X6: PASS | Y6: OK | Z6: - | AA6: NORMAL | AB6: =IF(OR(AA6="",C6=""),"",IF(C6="ATTACK",IF(AA6="ATTACK","TP","FN"),IF(AA6="ATTACK","FP","TN"))) -> TN
A7: N06 | B7: Operator relief valve step | C7: NORMAL | D7: - | E7: 127.0.0.1 | F7: 16 | G7: RELIEF_VALVE | H7: 46 | I7: valid | J7: 1 | K7: 12 | L7: 50 | M7: 0 | N7: 45 | O7: 60 | P7: 40 | Q7: 45 | S7: 45 -> 46 deg | T7: PASS | U7: OK | V7: PASS | W7: OK | X7: PASS | Y7: OK | Z7: - | AA7: NORMAL | AB7: =IF(OR(AA7="",C7=""),"",IF(C7="ATTACK",IF(AA7="ATTACK","TP","FN"),IF(AA7="ATTACK","FP","TN"))) -> TN
A8: N07 | B8: Heater high with cooling open | C8: NORMAL | D8: - | E8: 127.0.0.1 | F8: 16 | G8: HEATER_TEMP | H8: 112 | I8: valid | J8: 1 | K8: 10 | L8: 50 | M8: 0 | N8: 60 | O8: 102 | P8: 40 | Q8: 45 | S8: Legitimate multi-register combination: hot reactor but adequate cooling | T8: PASS | U8: OK | V8: PASS | W8: OK | X8: PASS | Y8: OK | Z8: - | AA8: NORMAL | AB8: =IF(OR(AA8="",C8=""),"",IF(C8="ATTACK",IF(AA8="ATTACK","TP","FN"),IF(AA8="ATTACK","FP","TN"))) -> TN
A9: N08 | B9: Pump high with relief open | C9: NORMAL | D9: - | E9: 127.0.0.1 | F9: 16 | G9: FEED_PUMP | H9: 75 | I9: valid | J9: 1 | K9: 10 | L9: 50 | M9: 0 | N9: 45 | O9: 60 | P9: 65 | Q9: 50 | S9: Legitimate multi-register combination: high feed with relief path open | T9: PASS | U9: OK | V9: PASS | W9: OK | X9: PASS | Y9: OK | Z9: - | AA9: NORMAL | AB9: =IF(OR(AA9="",C9=""),"",IF(C9="ATTACK",IF(AA9="ATTACK","TP","FN"),IF(AA9="ATTACK","FP","TN"))) -> TN
A10: N09 | B10: Relief nearly closed at low feed | C10: NORMAL | D10: - | E10: 127.0.0.1 | F10: 16 | G10: RELIEF_VALVE | H10: 12 | I10: valid | J10: 1 | K10: 10 | L10: 50 | M10: 0 | N10: 45 | O10: 60 | P10: 40 | Q10: 45 | S10: Relief low is safe because feed pump is low | T10: PASS | U10: OK | V10: PASS | W10: OK | X10: PASS | Y10: OK | Z10: - | AA10: NORMAL | AB10: =IF(OR(AA10="",C10=""),"",IF(C10="ATTACK",IF(AA10="ATTACK","TP","FN"),IF(AA10="ATTACK","FP","TN"))) -> TN
A11: N10 | B11: Cooling low at moderate heat | C11: NORMAL | D11: - | E11: 127.0.0.1 | F11: 16 | G11: COOLING_VALVE | H11: 20 | I11: valid | J11: 1 | K11: 10 | L11: 50 | M11: 0 | N11: 30 | O11: 80 | P11: 40 | Q11: 45 | S11: Cooling low is safe because heater setpoint is moderate | T11: PASS | U11: OK | V11: PASS | W11: OK | X11: PASS | Y11: OK | Z11: - | AA11: NORMAL | AB11: =IF(OR(AA11="",C11=""),"",IF(C11="ATTACK",IF(AA11="ATTACK","TP","FN"),IF(AA11="ATTACK","FP","TN"))) -> TN
A12: N11 | B12: Pressure up with warm heater | C12: NORMAL | D12: - | E12: 127.0.0.1 | F12: 16 | G12: TANK_PRESSURE | H12: 86 | I12: valid | J12: 1 | K12: 5 | L12: 80 | M12: 0 | N12: 45 | O12: 110 | P12: 40 | Q12: 45 | S12: Below HOT_PRESSURIZED_VESSEL heater threshold (125 C) | T12: PASS | U12: OK | V12: PASS | W12: OK | X12: PASS | Y12: OK | Z12: - | AA12: NORMAL | AB12: =IF(OR(AA12="",C12=""),"",IF(C12="ATTACK",IF(AA12="ATTACK","TP","FN"),IF(AA12="ATTACK","FP","TN"))) -> TN
A13: N12 | B13: Corrective move out of unsafe state | C13: NORMAL | D13: - | E13: 127.0.0.1 | F13: 16 | G13: FEED_PUMP | H13: 75 | I13: valid | J13: 1 | K13: 10 | L13: 50 | M13: 0 | N13: 45 | O13: 60 | P13: 80 | Q13: 10 | S13: Plant already in OVERPRESSURE combination; operator reduces pump | T13: PASS | U13: OK | V13: PASS | W13: OK | X13: PASS | Y13: OK | Z13: - | AA13: NORMAL | AB13: =IF(OR(AA13="",C13=""),"",IF(C13="ATTACK",IF(AA13="ATTACK","TP","FN"),IF(AA13="ATTACK","FP","TN"))) -> TN
... A15: N14 | B15: Second trusted SCADA host | C15: NORMAL | D15: - | E15: 192.168.1.10 | F15: 16 | G15: COOLING_VALVE | H15: 46 | I15: valid | J15: 1 | K15: 12 | L15: 50 | M15: 0 | N15: 45 | O15: 60 | P15: 40 | Q15: 45 | S15: Signed command from the other whitelisted SCADA address | T15: PASS | U15: OK | V15: PASS | W15: OK | X15: PASS | Y15: OK | Z15: - | AA15: NORMAL | AB15: =IF(OR(AA15="",C15=""),"",IF(C15="ATTACK",IF(AA15="ATTACK","TP","FN"),IF(AA15="ATTACK","FP","TN"))) -> TN
A16: N15 | B16: Pressure and heat both high but below limits | C16: NORMAL | D16: - | E16: 127.0.0.1 | F16: 16 | G16: HEATER_TEMP | H16: 124 | I16: valid | J16: 1 | K16: 10 | L16: 84 | M16: 0 | N16: 60 | O16: 115 | P16: 40 | Q16: 45 | T16: PASS | U16: OK | V16: PASS | W16: OK | X16: PASS | Y16: OK | Z16: - | AA16: NORMAL | AB16: =IF(OR(AA16="",C16=""),"",IF(C16="ATTACK",IF(AA16="ATTACK","TP","FN"),IF(AA16="ATTACK","FP","TN"))) -> TN
A17: N16 | B17: Fast conveyor, moderate pressure | C17: NORMAL | D17: - | E17: 127.0.0.1 | F17: 16 | G17: CONVEYOR_SPEED | H17: 110 | I17: valid | J17: 1 | K17: 5 | L17: 80 | M17: 100 | N17: 45 | O17: 60 | P17: 40 | Q17: 45 | T17: PASS | U17: OK | V17: PASS | W17: OK | X17: PASS | Y17: OK | Z17: - | AA17: NORMAL | AB17: =IF(OR(AA17="",C17=""),"",IF(C17="ATTACK",IF(AA17="ATTACK","TP","FN"),IF(AA17="ATTACK","FP","TN"))) -> TN
A18: N17 | B18: Cooling reduced at normal pressure | C18: NORMAL | D18: - | E18: 127.0.0.1 | F18: 16 | G18: COOLING_VALVE | H18: 44 | I18: valid | J18: 1 | K18: 5 | L18: 30 | M18: 0 | N18: 60 | O18: 60 | P18: 40 | Q18: 45 | T18: PASS | U18: OK | V18: PASS | W18: OK | X18: PASS | Y18: OK | Z18: - | AA18: NORMAL | AB18: =IF(OR(AA18="",C18=""),"",IF(C18="ATTACK",IF(AA18="ATTACK","TP","FN"),IF(AA18="ATTACK","FP","TN"))) -> TN
A19: N18 | B19: Emergency fast cooling open | C19: NORMAL | D19: - | E19: 127.0.0.1 | F19: 16 | G19: COOLING_VALVE | H19: 80 | I19: valid | J19: 1 | K19: 1 | L19: 50 | M19: 0 | N19: 45 | O19: 60 | P19: 40 | Q19: 45 | S19: Legitimate emergency action faster than the valve ramp (edge case) | T19: PASS | U19: OK | V19: FAIL | W19: RATE_OF_CHANGE_EXCEEDED:COOLING_VALVE Δ35.00 > max 5.50 in 1.000s | X19: DROP | Y19: RATE_OF_CHANGE_EXCEEDED:COOLING_VALVE Δ35.00 > max 5.50 in 1.000s | Z19: Rate-of-Change Violation | AA19: ATTACK | AB19: =IF(OR(AA19="",C19=""),"",IF(C19="ATTACK",IF(AA19="ATTACK","TP","FN"),IF(AA19="ATTACK","FP","TN"))) -> FP
A20: N19 | B20: Short operator burst | C20: NORMAL | D20: - | E20: 127.0.0.1 | F20: 16 | G20: RELIEF_VALVE | H20: 46 | I20: valid | J20: 3 | K20: 12 | L20: 50 | M20: 0 | N20: 45 | O20: 60 | P20: 40 | Q20: 45 | S20: 3 quick legitimate adjustments (below 5 req/s) | T20: PASS | U20: OK | V20: PASS | W20: OK | X20: PASS | Y20: OK | Z20: - | AA20: NORMAL | AB20: =IF(OR(AA20="",C20=""),"",IF(C20="ATTACK",IF(AA20="ATTACK","TP","FN"),IF(AA20="ATTACK","FP","TN"))) -> TN
A21: N20 | B21: Operator relief step | C21: NORMAL | D21: - | E21: 127.0.0.1 | F21: 16 | G21: RELIEF_VALVE | H21: 51 | I21: valid | J21: 1 | K21: 12 | L21: 50 | M21: 0 | N21: 45 | O21: 60 | P21: 40 | Q21: 50 | T21: PASS | U21: OK | V21: PASS | W21: OK | X21: PASS | Y21: OK | Z21: - | AA21: NORMAL | AB21: =IF(OR(AA21="",C21=""),"",IF(C21="ATTACK",IF(AA21="ATTACK","TP","FN"),IF(AA21="ATTACK","FP","TN"))) -> TN
A22: A01 | B22: Unsigned command | C22: ATTACK | D22: Missing HMAC (Unsigned Command) | E22: 127.0.0.1 | F22: 6 | G22: COOLING_VALVE | H22: 46 | I22: missing | J22: 1 | K22: 12 | L22: 50 | M22: 0 | N22: 45 | O22: 60 | P22: 40 | Q22: 45 | S22: Plain FC6 write with no HMAC | T22: FAIL | U22: HMAC_MISSING:command carried no HMAC signature | V22: PASS | W22: OK | X22: DROP | Y22: HMAC_MISSING:command carried no HMAC signature | Z22: Missing HMAC (Unsigned Command) | AA22: ATTACK | AB22: =IF(OR(AA22="",C22=""),"",IF(C22="ATTACK",IF(AA22="ATTACK","TP","FN"),IF(AA22="ATTACK","FP","TN"))) -> TP
A23: A02 | B23: Value tampered in transit | C23: ATTACK | D23: Tampered / Forged HMAC | E23: 127.0.0.1 | F23: 16 | G23: HEATER_TEMP | H23: 61 | I23: tampered | J23: 1 | K23: 12 | L23: 50 | M23: 0 | N23: 45 | O23: 60 | P23: 40 | Q23: 45 | S23: Signed 61 C, value changed to 140 C, original tag kept | T23: FAIL | U23: HMAC_INVALID:HMAC tag does not match command (tampered or wrong key) | V23: FAIL | W23: RATE_OF_CHANGE_EXCEEDED:HEATER_TEMP Δ80.00 > max 66.00 in 12.000s | X23: DROP | Y23: HMAC_INVALID:HMAC tag does not match command (tampered or wrong key) | Z23: Tampered / Forged HMAC | AA23: ATTACK | AB23: =IF(OR(AA23="",C23=""),"",IF(C23="ATTACK",IF(AA23="ATTACK","TP","FN"),IF(AA23="ATTACK","FP","TN"))) -> TP
A24: A03 | B24: Forged signature | C24: ATTACK | D24: Tampered / Forged HMAC | E24: 127.0.0.1 | F24: 16 | G24: COOLING_VALVE | H24: 46 | I24: wrong_key | J24: 1 | K24: 12 | L24: 50 | M24: 0 | N24: 45 | O24: 60 | P24: 40 | Q24: 45 | S24: Signed with an attacker-chosen key | T24: FAIL | U24: HMAC_INVALID:HMAC tag does not match command (tampered or wrong key) | V24: PASS | W24: OK | X24: DROP | Y24: HMAC_INVALID:HMAC tag does not match command (tampered or wrong key) | Z24: Tampered / Forged HMAC | AA24: ATTACK | AB24: =IF(OR(AA24="",C24=""),"",IF(C24="ATTACK",IF(AA24="ATTACK","TP","FN"),IF(AA24="ATTACK","FP","TN"))) -> TP
A25: A04 | B25: Delayed replay (expired) | C25: ATTACK | D25: Expired Signature (Delayed Replay) | E25: 127.0.0.1 | F25: 16 | G25: CONVEYOR_SPEED | H25: 2 | I25: expired | J25: 1 | K25: 12 | L25: 50 | M25: 0 | N25: 45 | O25: 60 | P25: 40 | Q25: 45 | S25: Correct signature, timestamp 5 minutes old | T25: FAIL | U25: HMAC_EXPIRED:signed timestamp outside +/-30s freshness window | V25: PASS | W25: OK | X25: DROP | Y25: HMAC_EXPIRED:signed timestamp outside +/-30s freshness window | Z25: Expired Signature (Delayed Replay) | AA25: ATTACK | AB25: =IF(OR(AA25="",C25=""),"",IF(C25="ATTACK",IF(AA25="ATTACK","TP","FN"),IF(AA25="ATTACK","FP","TN"))) -> TP
A26: A05 | B26: Immediate replay | C26: ATTACK | D26: Replay | E26: 127.0.0.1 | F26: 16 | G26: CONVEYOR_SPEED | H26: 2 | I26: replayed | J26: 1 | K26: 12 | L26: 50 | M26: 0 | N26: 45 | O26: 60 | P26: 40 | Q26: 45 | S26: Byte-identical signed frame sent twice; second is evaluated | T26: FAIL | U26: REPLAY_DETECTED:nonce reused | V26: PASS | W26: OK | X26: DROP | Y26: REPLAY_DETECTED:nonce reused | Z26: Replay | AA26: ATTACK | AB26: =IF(OR(AA26="",C26=""),"",IF(C26="ATTACK",IF(AA26="ATTACK","TP","FN"),IF(AA26="ATTACK","FP","TN"))) -> TP
A27: A06 | B27: Malformed signed frame | C27: ATTACK | D27: Malformed Signed Frame | E27: 127.0.0.1 | F27: 16 | G27: COOLING_VALVE | H27: 46 | I27: malformed | J27: 1 | K27: 12 | L27: 50 | M27: 0 | N27: 45 | O27: 60 | P27: 40 | Q27: 45 | S27: Truncated HMAC tag | T27: FAIL | U27: HMAC_MALFORMED:HMAC tag has wrong length | V27: PASS | W27: OK | X27: DROP | Y27: HMAC_MALFORMED:HMAC tag has wrong length | Z27: Malformed Signed Frame | AA27: ATTACK | AB27: =IF(OR(AA27="",C27=""),"",IF(C27="ATTACK",IF(AA27="ATTACK","TP","FN"),IF(AA27="ATTACK","FP","TN"))) -> TP
A28: A07 | B28: Rogue host with stolen key | C28: ATTACK | D28: Untrusted Source | E28: 10.0.0.99 | F28: 16 | G28: COOLING_VALVE | H28: 46 | I28: valid | J28: 1 | K28: 12 | L28: 50 | M28: 0 | N28: 45 | O28: 60 | P28: 40 | Q28: 45 | S28: Valid signature but connection from a non-SCADA address | T28: FAIL | U28: UNTRUSTED_SOURCE | V28: PASS | W28: OK | X28: DROP | Y28: UNTRUSTED_SOURCE | Z28: Untrusted Source | AA28: ATTACK | AB28: =IF(OR(AA28="",C28=""),"",IF(C28="ATTACK",IF(AA28="ATTACK","TP","FN"),IF(AA28="ATTACK","FP","TN"))) -> TP
A29: A08 | B29: Probe of unmapped register | C29: ATTACK | D29: Invalid Register Access | E29: 127.0.0.1 | F29: 16 | G29: 7 | H29: 10 | I29: valid | J29: 1 | K29: 12 | L29: 50 | M29: 0 | N29: 45 | O29: 60 | P29: 40 | Q29: 45 | S29: Write to address 7 (no such machine) | T29: FAIL | U29: INVALID_REGISTER | V29: FAIL | W29: UNKNOWN_REGISTER:7 | X29: DROP | Y29: INVALID_REGISTER | Z29: Invalid Register Access | AA29: ATTACK | AB29: =IF(OR(AA29="",C29=""),"",IF(C29="ATTACK",IF(AA29="ATTACK","TP","FN"),IF(AA29="ATTACK","FP","TN"))) -> TP
A30: A09 | B30: Invalid function code | C30: ATTACK | D30: Invalid Function Code | E30: 127.0.0.1 | F30: 5 | G30: CONVEYOR_SPEED | H30: 2 | I30: valid | J30: 1 | K30: 12 | L30: 50 | M30: 0 | N30: 45 | O30: 60 | P30: 40 | Q30: 45 | S30: FC5 (write coil) against a holding register | T30: FAIL | U30: INVALID_FUNCTION_CODE | V30: PASS | W30: OK | X30: DROP | Y30: INVALID_FUNCTION_CODE | Z30: Invalid Function Code | AA30: ATTACK | AB30: =IF(OR(AA30="",C30=""),"",IF(C30="ATTACK",IF(AA30="ATTACK","TP","FN"),IF(AA30="ATTACK","FP","TN"))) -> TP
A31: A10 | B31: Command flood | C31: ATTACK | D31: Flood / Rate Limit | E31: 127.0.0.1 | F31: 16 | G31: CONVEYOR_SPEED | H31: 2 | I31: valid | J31: 8 | K31: 12 | L31: 50 | M31: 0 | N31: 45 | O31: 60 | P31: 40 | Q31: 45 | S31: 8 signed commands in < 1 s; last one evaluated | T31: FAIL | U31: RATE_LIMIT_EXCEEDED | V31: PASS | W31: OK | X31: DROP | Y31: RATE_LIMIT_EXCEEDED | Z31: Flood / Rate Limit | AA31: ATTACK | AB31: =IF(OR(AA31="",C31=""),"",IF(C31="ATTACK",IF(AA31="ATTACK","TP","FN"),IF(AA31="ATTACK","FP","TN"))) -> TP
A32: A11 | B32: Impossible tank pressure | C32: ATTACK | D32: Impossible Command (Out of Bounds) | E32: 127.0.0.1 | F32: 16 | G32: TANK_PRESSURE | H32: 999 | I32: valid | J32: 1 | K32: 12 | L32: 50 | M32: 0 | N32: 45 | O32: 60 | P32: 40 | Q32: 45 | T32: PASS | U32: OK | V32: FAIL | W32: OUT_OF_BOUNDS:TANK_PRESSURE=999.00 (allowed 0–100) | X32: DROP | Y32: OUT_OF_BOUNDS:TANK_PRESSURE=999.00 (allowed 0–100) | Z32: Impossible Command (Out of Bounds) | AA32: ATTACK | AB32: =IF(OR(AA32="",C32=""),"",IF(C32="ATTACK",IF(AA32="ATTACK","TP","FN"),IF(AA32="ATTACK","FP","TN"))) -> TP
A33: A12 | B33: Impossible heater temperature | C33: ATTACK | D33: Impossible Command (Out of Bounds) | E33: 127.0.0.1 | F33: 16 | G33: HEATER_TEMP | H33: 180 | I33: valid | J33: 1 | K33: 12 | L33: 50 | M33: 0 | N33: 45 | O33: 60 | P33: 40 | Q33: 45 | T33: PASS | U33: OK | V33: FAIL | W33: OUT_OF_BOUNDS:HEATER_TEMP=180.00 (allowed 0–150) | X33: DROP | Y33: OUT_OF_BOUNDS:HEATER_TEMP=180.00 (allowed 0–150) | Z33: Impossible Command (Out of Bounds) | AA33: ATTACK | AB33: =IF(OR(AA33="",C33=""),"",IF(C33="ATTACK",IF(AA33="ATTACK","TP","FN"),IF(AA33="ATTACK","FP","TN"))) -> TP
A34: A13 | B34: Physically impossible ramp | C34: ATTACK | D34: Rate-of-Change Violation | E34: 127.0.0.1 | F34: 16 | G34: CONVEYOR_SPEED | H34: 100 | I34: valid | J34: 1 | K34: 0.2 | L34: 50 | M34: 0 | N34: 45 | O34: 60 | P34: 40 | Q34: 45 | S34: 0 -> 100 RPM in 0.2 s | T34: PASS | U34: OK | V34: FAIL | W34: RATE_OF_CHANGE_EXCEEDED:CONVEYOR_SPEED Δ100.00 > max 2.20 in 0.200s | X34: DROP | Y34: RATE_OF_CHANGE_EXCEEDED:CONVEYOR_SPEED Δ100.00 > max 2.20 in 0.200s | Z34: Rate-of-Change Violation | AA34: ATTACK | AB34: =IF(OR(AA34="",C34=""),"",IF(C34="ATTACK",IF(AA34="ATTACK","TP","FN"),IF(AA34="ATTACK","FP","TN"))) -> TP
A35: A14 | B35: Thermal runaway via heater | C35: ATTACK | D35: Cross-Register Correlation | E35: 127.0.0.1 | F35: 16 | G35: HEATER_TEMP | H35: 112 | I35: valid | J35: 1 | K35: 10 | L35: 50 | M35: 0 | N35: 20 | O35: 102 | P35: 40 | Q35: 45 | S35: Each value safe alone; heater 112 + cooling 20 is unsafe | T35: PASS | U35: OK | V35: FAIL | W35: CROSS_REGISTER_VIOLATION:THERMAL_RUNAWAY:HEATER_TEMP=112.0>=110 & COOLING_VALVE=20.0<=25 (heater setpoint high while cooling valve nearly closed - heat cannot be removed) | X35: DROP | Y35: CROSS_REGISTER_VIOLATION:THERMAL_RUNAWAY:HEATER_TEMP=112.0>=110 & COOLING_VALVE=20.0<=25 (heater setpoint high while cooling valve nearly closed - heat cannot be removed) | Z35: Cross-Register Correlation | AA35: ATTACK | AB35: =IF(OR(AA35="",C35=""),"",IF(C35="ATTACK",IF(AA35="ATTACK","TP","FN"),IF(AA35="ATTACK","FP","TN"))) -> TP
A36: A15 | B36: Thermal runaway via cooling valve | C36: ATTACK | D36: Cross-Register Correlation | E36: 127.0.0.1 | F36: 16 | G36: COOLING_VALVE | H36: 24 | I36: valid | J36: 1 | K36: 10 | L36: 50 | M36: 0 | N36: 30 | O36: 115 | P36: 40 | Q36: 45 | T36: PASS | U36: OK | V36: FAIL | W36: CROSS_REGISTER_VIOLATION:THERMAL_RUNAWAY:HEATER_TEMP=115.0>=110 & COOLING_VALVE=24.0<=25 (heater setpoint high while cooling valve nearly closed - heat cannot be removed) | X36: DROP | Y36: CROSS_REGISTER_VIOLATION:THERMAL_RUNAWAY:HEATER_TEMP=115.0>=110 & COOLING_VALVE=24.0<=25 (heater setpoint high while cooling valve nearly closed - heat cannot be removed) | Z36: Cross-Register Correlation | AA36: ATTACK | AB36: =IF(OR(AA36="",C36=""),"",IF(C36="ATTACK",IF(AA36="ATTACK","TP","FN"),IF(AA36="ATTACK","FP","TN"))) -> TP
A37: A16 | B37: Overpressure via feed pump | C37: ATTACK | D37: Cross-Register Correlation | E37: 127.0.0.1 | F37: 16 | G37: FEED_PUMP | H37: 75 | I37: valid | J37: 1 | K37: 10 | L37: 50 | M37: 0 | N37: 45 | O37: 60 | P37: 65 | Q37: 10 | T37: PASS | U37: OK | V37: FAIL | W37: CROSS_REGISTER_VIOLATION:OVERPRESSURE:FEED_PUMP=75.0>=70 & RELIEF_VALVE=10.0<=15 (feed pump driving flow into tank while relief valve nearly closed - tank cannot vent) | X37: DROP | Y37: CROSS_REGISTER_VIOLATION:OVERPRESSURE:FEED_PUMP=75.0>=70 & RELIEF_VALVE=10.0<=15 (feed pump driving flow into tank while relief valve nearly closed - tank cannot vent) | Z37: Cross-Register Correlation | AA37: ATTACK | AB37: =IF(OR(AA37="",C37=""),"",IF(C37="ATTACK",IF(AA37="ATTACK","TP","FN"),IF(AA37="ATTACK","FP","TN"))) -> TP
A38: A17 | B38: Overpressure via pending setpoint | C38: ATTACK | D38: Cross-Register Correlation | E38: 127.0.0.1 | F38: 16 | G38: FEED_PUMP | H38: 75 | I38: valid | J38: 1 | K38: 10 | L38: 50 | M38: 0 | N38: 45 | O38: 60 | P38: 65 | Q38: 40 | R38: {"RELIEF_VALVE": 10.0} | S38: Relief telemetry still 40 but an approved setpoint of 10 is ramping | T38: PASS | U38: OK | V38: FAIL | W38: CROSS_REGISTER_VIOLATION:OVERPRESSURE:FEED_PUMP=75.0>=70 & RELIEF_VALVE=10.0<=15 (feed pump driving flow into tank while relief valve nearly closed - tank cannot vent) | X38: DROP | Y38: CROSS_REGISTER_VIOLATION:OVERPRESSURE:FEED_PUMP=75.0>=70 & RELIEF_VALVE=10.0<=15 (feed pump driving flow into tank while relief valve nearly closed - tank cannot vent) | Z38: Cross-Register Correlation | AA38: ATTACK | AB38: =IF(OR(AA38="",C38=""),"",IF(C38="ATTACK",IF(AA38="ATTACK","TP","FN"),IF(AA38="ATTACK","FP","TN"))) -> TP
A39: A18 | B39: Hot pressurized vessel | C39: ATTACK | D39: Cross-Register Correlation | E39: 127.0.0.1 | F39: 16 | G39: TANK_PRESSURE | H39: 86 | I39: valid | J39: 1 | K39: 5 | L39: 80 | M39: 0 | N39: 45 | O39: 130 | P39: 40 | Q39: 45 | T39: PASS | U39: OK | V39: FAIL | W39: CROSS_REGISTER_VIOLATION:HOT_PRESSURIZED_VESSEL:TANK_PRESSURE=86.0>=85 & HEATER_TEMP=130.0>=125 (tank pressure and heater temperature both near limits at the same time) | X39: DROP | Y39: CROSS_REGISTER_VIOLATION:HOT_PRESSURIZED_VESSEL:TANK_PRESSURE=86.0>=85 & HEATER_TEMP=130.0>=125 (tank pressure and heater temperature both near limits at the same time) | Z39: Cross-Register Correlation | AA39: ATTACK | AB39: =IF(OR(AA39="",C39=""),"",IF(C39="ATTACK",IF(AA39="ATTACK","TP","FN"),IF(AA39="ATTACK","FP","TN"))) -> TP
A40: A19 | B40: Valve slam at low pressure | C40: ATTACK | D40: Cross-Register Correlation | E40: 127.0.0.1 | F40: 16 | G40: COOLING_VALVE | H40: 30 | I40: valid | J40: 1 | K40: 10 | L40: 8 | M40: 0 | N40: 60 | O40: 60 | P40: 40 | Q40: 45 | T40: PASS | U40: OK | V40: FAIL | W40: CROSS_REGISTER_VIOLATION:VALVE_CLOSING_LOW_PRESSURE:valve closing sharply with tank pressure already low | X40: DROP | Y40: CROSS_REGISTER_VIOLATION:VALVE_CLOSING_LOW_PRESSURE:valve closing sharply with tank pressure already low | Z40: Cross-Register Correlation | AA40: ATTACK | AB40: =IF(OR(AA40="",C40=""),"",IF(C40="ATTACK",IF(AA40="ATTACK","TP","FN"),IF(AA40="ATTACK","FP","TN"))) -> TP
A41: A20 | B41: Conveyor max at pressure limit | C41: ATTACK | D41: Cross-Register Correlation | E41: 127.0.0.1 | F41: 16 | G41: CONVEYOR_SPEED | H41: 110 | I41: valid | J41: 1 | K41: 5 | L41: 95 | M41: 100 | N41: 45 | O41: 60 | P41: 40 | Q41: 45 | T41: PASS | U41: OK | V41: FAIL | W41: CROSS_REGISTER_VIOLATION:CONVEYOR_PRESSURE_OVERLOAD:conveyor near max speed while tank pressure near limit | X41: DROP | Y41: CROSS_REGISTER_VIOLATION:CONVEYOR_PRESSURE_OVERLOAD:conveyor near max speed while tank pressure near limit | Z41: Cross-Register Correlation | AA41: ATTACK | AB41: =IF(OR(AA41="",C41=""),"",IF(C41="ATTACK",IF(AA41="ATTACK","TP","FN"),IF(AA41="ATTACK","FP","TN"))) -> TP
...

Sheet Results
A1: Industrial Mind - System Efficiency Results
A2: Evaluated 2026-09-23T17:04:37 over TestCases rows 2-43. Positive class = ATTACK. Formulas recalculate from TestCases.
A4: Metric | B4: Value (Excel formula) | C4: Value (evaluate_system.py) | D4: Check | E4: Definition
A5: Total Cases | B5: =COUNTIF(TestCases!$C$2:$C$43,"ATTACK")+COUNTIF(TestCases!$C$2:$C$43,"NORMAL") -> 42 | C5: 42 | D5: =IF(ABS(B5-C5)<0.000001,"OK","MISMATCH") -> OK | E5: labelled cases
A6: Actual Attacks | B6: =COUNTIF(TestCases!$C$2:$C$43,"ATTACK") -> 22 | C6: 22 | D6: =IF(ABS(B6-C6)<0.000001,"OK","MISMATCH") -> OK | E6: Actual Label = ATTACK
A7: Actual Normal | B7: =COUNTIF(TestCases!$C$2:$C$43,"NORMAL") -> 20 | C7: 20 | D7: =IF(ABS(B7-C7)<0.000001,"OK","MISMATCH") -> OK | E7: Actual Label = NORMAL
A8: TP | B8: =COUNTIFS(TestCases!$C$2:$C$43,"ATTACK",TestCases!$AA$2:$AA$43,"ATTACK") -> 20 | C8: 20 | D8: =IF(ABS(B8-C8)<0.000001,"OK","MISMATCH") -> OK | E8: attack correctly dropped
A9: TN | B9: =COUNTIFS(TestCases!$C$2:$C$43,"NORMAL",TestCases!$AA$2:$AA$43,"NORMAL") -> 19 | C9: 19 | D9: =IF(ABS(B9-C9)<0.000001,"OK","MISMATCH") -> OK | E9: normal command correctly passed
A10: FP | B10: =COUNTIFS(TestCases!$C$2:$C$43,"NORMAL",TestCases!$AA$2:$AA$43,"ATTACK") -> 1 | C10: 1 | D10: =IF(ABS(B10-C10)<0.000001,"OK","MISMATCH") -> OK | E10: normal command wrongly dropped
A11: FN | B11: =COUNTIFS(TestCases!$C$2:$C$43,"ATTACK",TestCases!$AA$2:$AA$43,"NORMAL") -> 2 | C11: 2 | D11: =IF(ABS(B11-C11)<0.000001,"OK","MISMATCH") -> OK | E11: attack wrongly passed
A12: Accuracy | B12: =IFERROR((B8+B9)/(B8+B9+B10+B11),0) -> 0.92857143 | C12: 0.92857143 | D12: =IF(ABS(B12-C12)<0.000001,"OK","MISMATCH") -> OK | E12: (TP+TN)/(TP+TN+FP+FN)
A13: Precision | B13: =IFERROR(B8/(B8+B10),0) -> 0.95238095 | C13: 0.95238095 | D13: =IF(ABS(B13-C13)<0.000001,"OK","MISMATCH") -> OK | E13: TP/(TP+FP)
A14: Recall | B14: =IFERROR(B8/(B8+B11),0) -> 0.90909091 | C14: 0.90909091 | D14: =IF(ABS(B14-C14)<0.000001,"OK","MISMATCH") -> OK | E14: TP/(TP+FN)
A15: F1-score | B15: =IFERROR(2*B13*B14/(B13+B14),0) -> 0.93023256 | C15: 0.93023256 | D15: =IF(ABS(B15-C15)<0.000001,"OK","MISMATCH") -> OK | E15: 2*Precision*Recall/(Precision+Recall)
A16: Detection Rate | B16: =IFERROR(B8/(B8+B11),0) -> 0.90909091 | C16: 0.90909091 | D16: =IF(ABS(B16-C16)<0.000001,"OK","MISMATCH") -> OK | E16: attacks detected / all attacks (= Recall)
A17: False Positive Rate | B17: =IFERROR(B10/(B10+B9),0) -> 0.05 | C17: 0.05 | D17: =IF(ABS(B17-C17)<0.000001,"OK","MISMATCH") -> OK | E17: FP/(FP+TN)
A18: Specificity | B18: =IFERROR(B9/(B9+B10),0) -> 0.95 | C18: 0.95 | D18: =IF(ABS(B18-C18)<0.000001,"OK","MISMATCH") -> OK | E18: TN/(TN+FP)
A20: Detection by attack type
A21: Expected Attack Type | B21: Attack Cases | C21: Detected (DROP) | D21: Detection Rate
A22: Cross-Register Correlation | B22: =COUNTIFS(TestCases!$D$2:$D$43,A22,TestCases!$C$2:$C$43,"ATTACK") -> 8 | C22: =COUNTIFS(TestCases!$D$2:$D$43,A22,TestCases!$C$2:$C$43,"ATTACK",TestCases!$AA$2:$AA$43,"ATTACK") -> 7 | D22: =IFERROR(C22/B22,0) -> 0.875
A23: Expired Signature (Delayed Replay) | B23: =COUNTIFS(TestCases!$D$2:$D$43,A23,TestCases!$C$2:$C$43,"ATTACK") -> 1 | C23: =COUNTIFS(TestCases!$D$2:$D$43,A23,TestCases!$C$2:$C$43,"ATTACK",TestCases!$AA$2:$AA$43,"ATTACK") -> 1 | D23: =IFERROR(C23/B23,0) -> 1
A24: Flood / Rate Limit | B24: =COUNTIFS(TestCases!$D$2:$D$43,A24,TestCases!$C$2:$C$43,"ATTACK") -> 1 | C24: =COUNTIFS(TestCases!$D$2:$D$43,A24,TestCases!$C$2:$C$43,"ATTACK",TestCases!$AA$2:$AA$43,"ATTACK") -> 1 | D24: =IFERROR(C24/B24,0) -> 1
A25: Impossible Command (Out of Bounds) | B25: =COUNTIFS(TestCases!$D$2:$D$43,A25,TestCases!$C$2:$C$43,"ATTACK") -> 2 | C25: =COUNTIFS(TestCases!$D$2:$D$43,A25,TestCases!$C$2:$C$43,"ATTACK",TestCases!$AA$2:$AA$43,"ATTACK") -> 2 | D25: =IFERROR(C25/B25,0) -> 1
A26: Invalid Function Code | B26: =COUNTIFS(TestCases!$D$2:$D$43,A26,TestCases!$C$2:$C$43,"ATTACK") -> 1 | C26: =COUNTIFS(TestCases!$D$2:$D$43,A26,TestCases!$C$2:$C$43,"ATTACK",TestCases!$AA$2:$AA$43,"ATTACK") -> 1 | D26: =IFERROR(C26/B26,0) -> 1
A27: Invalid Register Access | B27: =COUNTIFS(TestCases!$D$2:$D$43,A27,TestCases!$C$2:$C$43,"ATTACK") -> 1 | C27: =COUNTIFS(TestCases!$D$2:$D$43,A27,TestCases!$C$2:$C$43,"ATTACK",TestCases!$AA$2:$AA$43,"ATTACK") -> 1 | D27: =IFERROR(C27/B27,0) -> 1
A28: Malformed Signed Frame | B28: =COUNTIFS(TestCases!$D$2:$D$43,A28,TestCases!$C$2:$C$43,"ATTACK") -> 1 | C28: =COUNTIFS(TestCases!$D$2:$D$43,A28,TestCases!$C$2:$C$43,"ATTACK",TestCases!$AA$2:$AA$43,"ATTACK") -> 1 | D28: =IFERROR(C28/B28,0) -> 1
A29: Missing HMAC (Unsigned Command) | B29: =COUNTIFS(TestCases!$D$2:$D$43,A29,TestCases!$C$2:$C$43,"ATTACK") -> 1 | C29: =COUNTIFS(TestCases!$D$2:$D$43,A29,TestCases!$C$2:$C$43,"ATTACK",TestCases!$AA$2:$AA$43,"ATTACK") -> 1 | D29: =IFERROR(C29/B29,0) -> 1
A30: Rate-of-Change Violation | B30: =COUNTIFS(TestCases!$D$2:$D$43,A30,TestCases!$C$2:$C$43,"ATTACK") -> 1 | C30: =COUNTIFS(TestCases!$D$2:$D$43,A30,TestCases!$C$2:$C$43,"ATTACK",TestCases!$AA$2:$AA$43,"ATTACK") -> 1 | D30: =IFERROR(C30/B30,0) -> 1
A31: Replay | B31: =COUNTIFS(TestCases!$D$2:$D$43,A31,TestCases!$C$2:$C$43,"ATTACK") -> 1 | C31: =COUNTIFS(TestCases!$D$2:$D$43,A31,TestCases!$C$2:$C$43,"ATTACK",TestCases!$AA$2:$AA$43,"ATTACK") -> 1 | D31: =IFERROR(C31/B31,0) -> 1
A32: Stealthy In-Bounds Manipulation | B32: =COUNTIFS(TestCases!$D$2:$D$43,A32,TestCases!$C$2:$C$43,"ATTACK") -> 1 | C32: =COUNTIFS(TestCases!$D$2:$D$43,A32,TestCases!$C$2:$C$43,"ATTACK",TestCases!$AA$2:$AA$43,"ATTACK") -> 0 | D32: =IFERROR(C32/B32,0) -> 0
A33: Tampered / Forged HMAC | B33: =COUNTIFS(TestCases!$D$2:$D$43,A33,TestCases!$C$2:$C$43,"ATTACK") -> 2 | C33: =COUNTIFS(TestCases!$D$2:$D$43,A33,TestCases!$C$2:$C$43,"ATTACK",TestCases!$AA$2:$AA$43,"ATTACK") -> 2 | D33: =IFERROR(C33/B33,0) -> 1
A34: Untrusted Source | B34: =COUNTIFS(TestCases!$D$2:$D$43,A34,TestCases!$C$2:$C$43,"ATTACK") -> 1 | C34: =COUNTIFS(TestCases!$D$2:$D$43,A34,TestCases!$C$2:$C$43,"ATTACK",TestCases!$AA$2:$AA$43,"ATTACK") -> 1 | D34: =IFERROR(C34/B34,0) -> 1

Sheet Confusion Matrix
A1: Confusion Matrix (positive class = ATTACK)
A3: Actual \ Predicted | B3: Predicted ATTACK | C3: Predicted NORMAL | D3: Total
A4: Actual ATTACK | B4: =Results!B8 -> 20 | C4: =Results!B11 -> 2 | D4: =B4+C4 -> 22
A5: Actual NORMAL | B5: =Results!B10 -> 1 | C5: =Results!B9 -> 19 | D5: =B5+C5 -> 20
A6: Total | B6: =B4+B5 -> 21 | C6: =C4+C5 -> 21 | D6: =D4+D5 -> 42
A8: TP = Actual ATTACK & Predicted ATTACK · FN = Actual ATTACK & Predicted NORMAL · FP = Actual NORMAL & Predicted ATTACK · TN = Actual NORMAL & Predicted NORMAL

Sheet README
A1: Industrial Mind - System Efficiency Test Data
A3: Blue columns (TestCases A..S) are INPUTS you may edit or extend with new rows.
A4: Green columns are OUTPUTS written by evaluation/evaluate_system.py - do not edit by hand.
A5: Actual Label is the ground truth: NORMAL or ATTACK. Positive class = ATTACK.
A6: Predicted Label = ATTACK when the real Orchestrator decision is DROP, NORMAL when PASS.
A8: Column meanings
A9: Machine Register: machine name from docs/interfaces.MACHINES (e.g. HEATER_TEMP) or a raw address number.
A10: Signature Mode: valid | missing | tampered | wrong_key | expired | replayed | malformed.
A11: Repeat Count: number of back-to-back sends from the same source; the LAST one is evaluated (flood tests).
A12: Seconds Since Last Settle: time the register has had to move since it last settled (rate-of-change check).
A13: Current <MACHINE>: live PLC telemetry for each machine when the command arrives.
A14: Pending Setpoints (JSON): approved targets still ramping, e.g. {"RELIEF_VALVE": 10}.
... A20: Results and Confusion Matrix sheets are rebuilt with Excel formulas over TestCases on every run.
